package com.practicalunittesting.updated;

import com.practicalunittesting.MyList;
import org.junit.Test;

import static com.googlecode.catchexception.CatchException.catchException;
import static com.googlecode.catchexception.CatchException.caughtException;
import static org.fest.assertions.Assertions.assertThat;
import static org.junit.Assert.fail;

public class MyListTryCatchTest {

    @Test
    public void shouldThrowExceptionWhenTryingToGetElementOutsideTheList() {
        MyList<Integer> list = new MyList<Integer>();
        list.add(0);
        list.add(1);
        list.add(2);
        try {
            list.get(3);
            fail("Expected IndexOutOfBoundsException but none has been thrown!");
        }
        catch(IndexOutOfBoundsException ioobe) {
         // fine, this is what we wanted
        }
    }
}
